2025-02-07T17:25:23 {"block_run_id": 164, "block_uuid": "loading_data", "pipeline_run_id": 18, "pipeline_schedule_id": 1, "pipeline_uuid": "training_models", "hostname": "58c38f4dbaa8", "block_type": "data_loader", "level": "INFO", "message": "Start executing block with BlockExecutor.", "timestamp": 1738949123.978526, "uuid": "b838db8316f3497d8740c238b7ee30a3"}
2025-02-07T17:25:23 {"block_run_id": 164, "block_uuid": "loading_data", "pipeline_run_id": 18, "pipeline_schedule_id": 1, "pipeline_uuid": "training_models", "hostname": "58c38f4dbaa8", "block_type": "data_loader", "level": "WARNING", "message": "Exception thrown when attempting to run <function BlockExecutor.execute.<locals>.__execute_with_retry at 0x7fc25e142170>, attempt 1 of 1", "timestamp": 1738949123.990122, "uuid": "487f617683914dd6a334dc1c827b211c", "error": "Traceback (most recent call last):\n  File \"/usr/local/lib/python3.10/site-packages/mage_ai/shared/retry.py\", line 38, in retry_func\n    return func(*args, **kwargs)\n  File \"/usr/local/lib/python3.10/site-packages/mage_ai/data_preparation/executors/block_executor.py\", line 621, in __execute_with_retry\n    return self._execute(\n  File \"/usr/local/lib/python3.10/site-packages/mage_ai/data_preparation/executors/block_executor.py\", line 1154, in _execute\n    result = self.block.execute_sync(\n  File \"/usr/local/lib/python3.10/site-packages/mage_ai/data_preparation/models/block/__init__.py\", line 1691, in execute_sync\n    return __execute()\n  File \"/usr/local/lib/python3.10/site-packages/mage_ai/data_preparation/models/block/__init__.py\", line 1668, in __execute\n    raise err\n  File \"/usr/local/lib/python3.10/site-packages/mage_ai/data_preparation/models/block/__init__.py\", line 1570, in __execute\n    output = self.execute_block(\n  File \"/usr/local/lib/python3.10/site-packages/mage_ai/data_preparation/models/block/__init__.py\", line 1910, in execute_block\n    outputs = self._execute_block(\n  File \"/usr/local/lib/python3.10/site-packages/mage_ai/data_preparation/models/block/__init__.py\", line 2041, in _execute_block\n    exec(self.content, results)\n  File \"<string>\", line 5, in <module>\nModuleNotFoundError: No module named 'opendatasets'\n", "error_stack": ["  File \"/usr/local/bin/mage\", line 8, in <module>\n    sys.exit(app())\n", "  File \"/usr/local/lib/python3.10/site-packages/typer/main.py\", line 311, in __call__\n    return get_command(self)(*args, **kwargs)\n", "  File \"/usr/local/lib/python3.10/site-packages/click/core.py\", line 1130, in __call__\n    return self.main(*args, **kwargs)\n", "  File \"/usr/local/lib/python3.10/site-packages/typer/core.py\", line 778, in main\n    return _main(\n", "  File \"/usr/local/lib/python3.10/site-packages/typer/core.py\", line 216, in _main\n    rv = self.invoke(ctx)\n", "  File \"/usr/local/lib/python3.10/site-packages/click/core.py\", line 1657, in invoke\n    return _process_result(sub_ctx.command.invoke(sub_ctx))\n", "  File \"/usr/local/lib/python3.10/site-packages/click/core.py\", line 1404, in invoke\n    return ctx.invoke(self.callback, **ctx.params)\n", "  File \"/usr/local/lib/python3.10/site-packages/click/core.py\", line 760, in invoke\n    return __callback(*args, **kwargs)\n", "  File \"/usr/local/lib/python3.10/site-packages/typer/main.py\", line 683, in wrapper\n    return callback(**use_params)  # type: ignore\n", "  File \"/usr/local/lib/python3.10/site-packages/mage_ai/cli/main.py\", line 147, in start\n    start_server(\n", "  File \"/usr/local/lib/python3.10/site-packages/mage_ai/server/server.py\", line 809, in start_server\n    scheduler_manager.start_scheduler()\n", "  File \"/usr/local/lib/python3.10/site-packages/mage_ai/server/scheduler_manager.py\", line 106, in start_scheduler\n    proc.start()\n", "  File \"/usr/local/lib/python3.10/multiprocessing/process.py\", line 121, in start\n    self._popen = self._Popen(self)\n", "  File \"/usr/local/lib/python3.10/multiprocessing/context.py\", line 224, in _Popen\n    return _default_context.get_context().Process._Popen(process_obj)\n", "  File \"/usr/local/lib/python3.10/multiprocessing/context.py\", line 281, in _Popen\n    return Popen(process_obj)\n", "  File \"/usr/local/lib/python3.10/multiprocessing/popen_fork.py\", line 19, in __init__\n    self._launch(process_obj)\n", "  File \"/usr/local/lib/python3.10/multiprocessing/popen_fork.py\", line 71, in _launch\n    code = process_obj._bootstrap(parent_sentinel=child_r)\n", "  File \"/usr/local/lib/python3.10/multiprocessing/process.py\", line 314, in _bootstrap\n    self.run()\n", "  File \"/usr/local/lib/python3.10/multiprocessing/process.py\", line 108, in run\n    self._target(*self._args, **self._kwargs)\n", "  File \"/usr/local/lib/python3.10/site-packages/mage_ai/orchestration/db/process.py\", line 15, in start_session_and_run\n    results = target(*args)\n", "  File \"/usr/local/lib/python3.10/site-packages/mage_ai/server/scheduler_manager.py\", line 58, in run_scheduler\n    LoopTimeTrigger().start()\n", "  File \"/usr/local/lib/python3.10/site-packages/mage_ai/orchestration/triggers/loop_time_trigger.py\", line 14, in start\n    self.run()\n", "  File \"/usr/local/lib/python3.10/site-packages/mage_ai/orchestration/triggers/time_trigger.py\", line 11, in run\n    schedule_all()\n", "  File \"/usr/local/lib/python3.10/site-packages/mage_ai/orchestration/pipeline_scheduler_original.py\", line 1702, in schedule_all\n    PipelineScheduler(r).start()\n", "  File \"/usr/local/lib/python3.10/site-packages/mage_ai/orchestration/db/__init__.py\", line 158, in func_with_rollback\n    return func(*args, **kwargs)\n", "  File \"/usr/local/lib/python3.10/site-packages/mage_ai/orchestration/pipeline_scheduler_original.py\", line 197, in start\n    self.schedule()\n", "  File \"/usr/local/lib/python3.10/site-packages/mage_ai/orchestration/db/__init__.py\", line 158, in func_with_rollback\n    return func(*args, **kwargs)\n", "  File \"/usr/local/lib/python3.10/site-packages/mage_ai/orchestration/pipeline_scheduler_original.py\", line 333, in schedule\n    self.__schedule_blocks(block_runs)\n", "  File \"/usr/local/lib/python3.10/site-packages/mage_ai/orchestration/pipeline_scheduler_original.py\", line 640, in __schedule_blocks\n    job_manager.add_job(\n", "  File \"/usr/local/lib/python3.10/site-packages/mage_ai/orchestration/job_manager.py\", line 20, in add_job\n    self.queue.enqueue(job_id, target, *args, **kwargs)\n", "  File \"/usr/local/lib/python3.10/site-packages/mage_ai/orchestration/queue/process_queue.py\", line 121, in enqueue\n    self.start_worker_pool()\n", "  File \"/usr/local/lib/python3.10/site-packages/mage_ai/orchestration/queue/process_queue.py\", line 198, in start_worker_pool\n    self.worker_pool_proc.start()\n", "  File \"/usr/local/lib/python3.10/multiprocessing/process.py\", line 121, in start\n    self._popen = self._Popen(self)\n", "  File \"/usr/local/lib/python3.10/multiprocessing/context.py\", line 224, in _Popen\n    return _default_context.get_context().Process._Popen(process_obj)\n", "  File \"/usr/local/lib/python3.10/multiprocessing/context.py\", line 281, in _Popen\n    return Popen(process_obj)\n", "  File \"/usr/local/lib/python3.10/multiprocessing/popen_fork.py\", line 19, in __init__\n    self._launch(process_obj)\n", "  File \"/usr/local/lib/python3.10/multiprocessing/popen_fork.py\", line 71, in _launch\n    code = process_obj._bootstrap(parent_sentinel=child_r)\n", "  File \"/usr/local/lib/python3.10/multiprocessing/process.py\", line 314, in _bootstrap\n    self.run()\n", "  File \"/usr/local/lib/python3.10/multiprocessing/process.py\", line 108, in run\n    self._target(*self._args, **self._kwargs)\n", "  File \"/usr/local/lib/python3.10/site-packages/mage_ai/orchestration/queue/process_queue.py\", line 351, in poll_job_and_execute\n    worker.start()\n", "  File \"/usr/local/lib/python3.10/multiprocessing/process.py\", line 121, in start\n    self._popen = self._Popen(self)\n", "  File \"/usr/local/lib/python3.10/multiprocessing/context.py\", line 224, in _Popen\n    return _default_context.get_context().Process._Popen(process_obj)\n", "  File \"/usr/local/lib/python3.10/multiprocessing/context.py\", line 281, in _Popen\n    return Popen(process_obj)\n", "  File \"/usr/local/lib/python3.10/multiprocessing/popen_fork.py\", line 19, in __init__\n    self._launch(process_obj)\n", "  File \"/usr/local/lib/python3.10/multiprocessing/popen_fork.py\", line 71, in _launch\n    code = process_obj._bootstrap(parent_sentinel=child_r)\n", "  File \"/usr/local/lib/python3.10/multiprocessing/process.py\", line 314, in _bootstrap\n    self.run()\n", "  File \"/usr/local/lib/python3.10/site-packages/newrelic/api/background_task.py\", line 117, in wrapper\n    return wrapped(*args, **kwargs)\n", "  File \"/usr/local/lib/python3.10/site-packages/mage_ai/orchestration/queue/process_queue.py\", line 315, in run\n    start_session_and_run(args[1], *args[2], **args[3])\n", "  File \"/usr/local/lib/python3.10/site-packages/mage_ai/orchestration/db/process.py\", line 15, in start_session_and_run\n    results = target(*args)\n", "  File \"/usr/local/lib/python3.10/site-packages/mage_ai/orchestration/pipeline_scheduler_original.py\", line 1235, in run_block\n    return ExecutorFactory.get_block_executor(\n", "  File \"/usr/local/lib/python3.10/site-packages/mage_ai/data_preparation/executors/block_executor.py\", line 647, in execute\n    result = __execute_with_retry()\n", "  File \"/usr/local/lib/python3.10/site-packages/mage_ai/shared/retry.py\", line 46, in retry_func\n    logger.warning(\n", "  File \"/usr/local/lib/python3.10/site-packages/mage_ai/data_preparation/logging/logger.py\", line 39, in warning\n    self.__send_message('warning', message, **kwargs)\n", "  File \"/usr/local/lib/python3.10/site-packages/mage_ai/data_preparation/logging/logger.py\", line 65, in __send_message\n    data['error_stack'] = traceback.format_stack()\n"], "error_stacktrace": "No module named 'opendatasets'"}
2025-02-07T17:25:23 {"block_run_id": 164, "block_uuid": "loading_data", "pipeline_run_id": 18, "pipeline_schedule_id": 1, "pipeline_uuid": "training_models", "hostname": "58c38f4dbaa8", "block_type": "data_loader", "level": "EXCEPTION", "message": "Failed to execute block loading_data", "timestamp": 1738949123.994758, "uuid": "607c2f77ee29460d828d9889e4466bb5", "error": "Traceback (most recent call last):\n  File \"/usr/local/lib/python3.10/site-packages/mage_ai/data_preparation/executors/block_executor.py\", line 647, in execute\n    result = __execute_with_retry()\n  File \"/usr/local/lib/python3.10/site-packages/mage_ai/shared/retry.py\", line 54, in retry_func\n    raise e\n  File \"/usr/local/lib/python3.10/site-packages/mage_ai/shared/retry.py\", line 38, in retry_func\n    return func(*args, **kwargs)\n  File \"/usr/local/lib/python3.10/site-packages/mage_ai/data_preparation/executors/block_executor.py\", line 621, in __execute_with_retry\n    return self._execute(\n  File \"/usr/local/lib/python3.10/site-packages/mage_ai/data_preparation/executors/block_executor.py\", line 1154, in _execute\n    result = self.block.execute_sync(\n  File \"/usr/local/lib/python3.10/site-packages/mage_ai/data_preparation/models/block/__init__.py\", line 1691, in execute_sync\n    return __execute()\n  File \"/usr/local/lib/python3.10/site-packages/mage_ai/data_preparation/models/block/__init__.py\", line 1668, in __execute\n    raise err\n  File \"/usr/local/lib/python3.10/site-packages/mage_ai/data_preparation/models/block/__init__.py\", line 1570, in __execute\n    output = self.execute_block(\n  File \"/usr/local/lib/python3.10/site-packages/mage_ai/data_preparation/models/block/__init__.py\", line 1910, in execute_block\n    outputs = self._execute_block(\n  File \"/usr/local/lib/python3.10/site-packages/mage_ai/data_preparation/models/block/__init__.py\", line 2041, in _execute_block\n    exec(self.content, results)\n  File \"<string>\", line 5, in <module>\nModuleNotFoundError: No module named 'opendatasets'\n", "error_stack": ["  File \"/usr/local/bin/mage\", line 8, in <module>\n    sys.exit(app())\n", "  File \"/usr/local/lib/python3.10/site-packages/typer/main.py\", line 311, in __call__\n    return get_command(self)(*args, **kwargs)\n", "  File \"/usr/local/lib/python3.10/site-packages/click/core.py\", line 1130, in __call__\n    return self.main(*args, **kwargs)\n", "  File \"/usr/local/lib/python3.10/site-packages/typer/core.py\", line 778, in main\n    return _main(\n", "  File \"/usr/local/lib/python3.10/site-packages/typer/core.py\", line 216, in _main\n    rv = self.invoke(ctx)\n", "  File \"/usr/local/lib/python3.10/site-packages/click/core.py\", line 1657, in invoke\n    return _process_result(sub_ctx.command.invoke(sub_ctx))\n", "  File \"/usr/local/lib/python3.10/site-packages/click/core.py\", line 1404, in invoke\n    return ctx.invoke(self.callback, **ctx.params)\n", "  File \"/usr/local/lib/python3.10/site-packages/click/core.py\", line 760, in invoke\n    return __callback(*args, **kwargs)\n", "  File \"/usr/local/lib/python3.10/site-packages/typer/main.py\", line 683, in wrapper\n    return callback(**use_params)  # type: ignore\n", "  File \"/usr/local/lib/python3.10/site-packages/mage_ai/cli/main.py\", line 147, in start\n    start_server(\n", "  File \"/usr/local/lib/python3.10/site-packages/mage_ai/server/server.py\", line 809, in start_server\n    scheduler_manager.start_scheduler()\n", "  File \"/usr/local/lib/python3.10/site-packages/mage_ai/server/scheduler_manager.py\", line 106, in start_scheduler\n    proc.start()\n", "  File \"/usr/local/lib/python3.10/multiprocessing/process.py\", line 121, in start\n    self._popen = self._Popen(self)\n", "  File \"/usr/local/lib/python3.10/multiprocessing/context.py\", line 224, in _Popen\n    return _default_context.get_context().Process._Popen(process_obj)\n", "  File \"/usr/local/lib/python3.10/multiprocessing/context.py\", line 281, in _Popen\n    return Popen(process_obj)\n", "  File \"/usr/local/lib/python3.10/multiprocessing/popen_fork.py\", line 19, in __init__\n    self._launch(process_obj)\n", "  File \"/usr/local/lib/python3.10/multiprocessing/popen_fork.py\", line 71, in _launch\n    code = process_obj._bootstrap(parent_sentinel=child_r)\n", "  File \"/usr/local/lib/python3.10/multiprocessing/process.py\", line 314, in _bootstrap\n    self.run()\n", "  File \"/usr/local/lib/python3.10/multiprocessing/process.py\", line 108, in run\n    self._target(*self._args, **self._kwargs)\n", "  File \"/usr/local/lib/python3.10/site-packages/mage_ai/orchestration/db/process.py\", line 15, in start_session_and_run\n    results = target(*args)\n", "  File \"/usr/local/lib/python3.10/site-packages/mage_ai/server/scheduler_manager.py\", line 58, in run_scheduler\n    LoopTimeTrigger().start()\n", "  File \"/usr/local/lib/python3.10/site-packages/mage_ai/orchestration/triggers/loop_time_trigger.py\", line 14, in start\n    self.run()\n", "  File \"/usr/local/lib/python3.10/site-packages/mage_ai/orchestration/triggers/time_trigger.py\", line 11, in run\n    schedule_all()\n", "  File \"/usr/local/lib/python3.10/site-packages/mage_ai/orchestration/pipeline_scheduler_original.py\", line 1702, in schedule_all\n    PipelineScheduler(r).start()\n", "  File \"/usr/local/lib/python3.10/site-packages/mage_ai/orchestration/db/__init__.py\", line 158, in func_with_rollback\n    return func(*args, **kwargs)\n", "  File \"/usr/local/lib/python3.10/site-packages/mage_ai/orchestration/pipeline_scheduler_original.py\", line 197, in start\n    self.schedule()\n", "  File \"/usr/local/lib/python3.10/site-packages/mage_ai/orchestration/db/__init__.py\", line 158, in func_with_rollback\n    return func(*args, **kwargs)\n", "  File \"/usr/local/lib/python3.10/site-packages/mage_ai/orchestration/pipeline_scheduler_original.py\", line 333, in schedule\n    self.__schedule_blocks(block_runs)\n", "  File \"/usr/local/lib/python3.10/site-packages/mage_ai/orchestration/pipeline_scheduler_original.py\", line 640, in __schedule_blocks\n    job_manager.add_job(\n", "  File \"/usr/local/lib/python3.10/site-packages/mage_ai/orchestration/job_manager.py\", line 20, in add_job\n    self.queue.enqueue(job_id, target, *args, **kwargs)\n", "  File \"/usr/local/lib/python3.10/site-packages/mage_ai/orchestration/queue/process_queue.py\", line 121, in enqueue\n    self.start_worker_pool()\n", "  File \"/usr/local/lib/python3.10/site-packages/mage_ai/orchestration/queue/process_queue.py\", line 198, in start_worker_pool\n    self.worker_pool_proc.start()\n", "  File \"/usr/local/lib/python3.10/multiprocessing/process.py\", line 121, in start\n    self._popen = self._Popen(self)\n", "  File \"/usr/local/lib/python3.10/multiprocessing/context.py\", line 224, in _Popen\n    return _default_context.get_context().Process._Popen(process_obj)\n", "  File \"/usr/local/lib/python3.10/multiprocessing/context.py\", line 281, in _Popen\n    return Popen(process_obj)\n", "  File \"/usr/local/lib/python3.10/multiprocessing/popen_fork.py\", line 19, in __init__\n    self._launch(process_obj)\n", "  File \"/usr/local/lib/python3.10/multiprocessing/popen_fork.py\", line 71, in _launch\n    code = process_obj._bootstrap(parent_sentinel=child_r)\n", "  File \"/usr/local/lib/python3.10/multiprocessing/process.py\", line 314, in _bootstrap\n    self.run()\n", "  File \"/usr/local/lib/python3.10/multiprocessing/process.py\", line 108, in run\n    self._target(*self._args, **self._kwargs)\n", "  File \"/usr/local/lib/python3.10/site-packages/mage_ai/orchestration/queue/process_queue.py\", line 351, in poll_job_and_execute\n    worker.start()\n", "  File \"/usr/local/lib/python3.10/multiprocessing/process.py\", line 121, in start\n    self._popen = self._Popen(self)\n", "  File \"/usr/local/lib/python3.10/multiprocessing/context.py\", line 224, in _Popen\n    return _default_context.get_context().Process._Popen(process_obj)\n", "  File \"/usr/local/lib/python3.10/multiprocessing/context.py\", line 281, in _Popen\n    return Popen(process_obj)\n", "  File \"/usr/local/lib/python3.10/multiprocessing/popen_fork.py\", line 19, in __init__\n    self._launch(process_obj)\n", "  File \"/usr/local/lib/python3.10/multiprocessing/popen_fork.py\", line 71, in _launch\n    code = process_obj._bootstrap(parent_sentinel=child_r)\n", "  File \"/usr/local/lib/python3.10/multiprocessing/process.py\", line 314, in _bootstrap\n    self.run()\n", "  File \"/usr/local/lib/python3.10/site-packages/newrelic/api/background_task.py\", line 117, in wrapper\n    return wrapped(*args, **kwargs)\n", "  File \"/usr/local/lib/python3.10/site-packages/mage_ai/orchestration/queue/process_queue.py\", line 315, in run\n    start_session_and_run(args[1], *args[2], **args[3])\n", "  File \"/usr/local/lib/python3.10/site-packages/mage_ai/orchestration/db/process.py\", line 15, in start_session_and_run\n    results = target(*args)\n", "  File \"/usr/local/lib/python3.10/site-packages/mage_ai/orchestration/pipeline_scheduler_original.py\", line 1235, in run_block\n    return ExecutorFactory.get_block_executor(\n", "  File \"/usr/local/lib/python3.10/site-packages/mage_ai/data_preparation/executors/block_executor.py\", line 649, in execute\n    self.logger.exception(\n", "  File \"/usr/local/lib/python3.10/site-packages/mage_ai/data_preparation/logging/logger.py\", line 30, in exception\n    self.__send_message('exception', message, **kwargs)\n", "  File \"/usr/local/lib/python3.10/site-packages/mage_ai/data_preparation/logging/logger.py\", line 65, in __send_message\n    data['error_stack'] = traceback.format_stack()\n"], "error_stacktrace": "No module named 'opendatasets'"}
Traceback (most recent call last):
  File "/usr/local/lib/python3.10/site-packages/mage_ai/data_preparation/executors/block_executor.py", line 647, in execute
    result = __execute_with_retry()
  File "/usr/local/lib/python3.10/site-packages/mage_ai/shared/retry.py", line 54, in retry_func
    raise e
  File "/usr/local/lib/python3.10/site-packages/mage_ai/shared/retry.py", line 38, in retry_func
    return func(*args, **kwargs)
  File "/usr/local/lib/python3.10/site-packages/mage_ai/data_preparation/executors/block_executor.py", line 621, in __execute_with_retry
    return self._execute(
  File "/usr/local/lib/python3.10/site-packages/mage_ai/data_preparation/executors/block_executor.py", line 1154, in _execute
    result = self.block.execute_sync(
  File "/usr/local/lib/python3.10/site-packages/mage_ai/data_preparation/models/block/__init__.py", line 1691, in execute_sync
    return __execute()
  File "/usr/local/lib/python3.10/site-packages/mage_ai/data_preparation/models/block/__init__.py", line 1668, in __execute
    raise err
  File "/usr/local/lib/python3.10/site-packages/mage_ai/data_preparation/models/block/__init__.py", line 1570, in __execute
    output = self.execute_block(
  File "/usr/local/lib/python3.10/site-packages/mage_ai/data_preparation/models/block/__init__.py", line 1910, in execute_block
    outputs = self._execute_block(
  File "/usr/local/lib/python3.10/site-packages/mage_ai/data_preparation/models/block/__init__.py", line 2041, in _execute_block
    exec(self.content, results)
  File "<string>", line 5, in <module>
ModuleNotFoundError: No module named 'opendatasets'
2025-02-07T17:26:41 {"block_run_id": 174, "block_uuid": "loading_data", "pipeline_run_id": 19, "pipeline_schedule_id": 1, "pipeline_uuid": "training_models", "hostname": "58c38f4dbaa8", "block_type": "data_loader", "level": "INFO", "message": "Start executing block with BlockExecutor.", "timestamp": 1738949201.060777, "uuid": "d60619c6eb9042ba9da261061c0b5b8d"}
2025-02-07T17:26:41 {"block_run_id": 174, "block_uuid": "loading_data", "pipeline_run_id": 19, "pipeline_schedule_id": 1, "pipeline_uuid": "training_models", "hostname": "58c38f4dbaa8", "block_type": "data_loader", "level": "WARNING", "message": "Exception thrown when attempting to run <function BlockExecutor.execute.<locals>.__execute_with_retry at 0x7fc25e162050>, attempt 1 of 1", "timestamp": 1738949201.072538, "uuid": "6aa84ca57bb74fbabf165a82c5c1be7b", "error": "Traceback (most recent call last):\n  File \"/usr/local/lib/python3.10/site-packages/mage_ai/shared/retry.py\", line 38, in retry_func\n    return func(*args, **kwargs)\n  File \"/usr/local/lib/python3.10/site-packages/mage_ai/data_preparation/executors/block_executor.py\", line 621, in __execute_with_retry\n    return self._execute(\n  File \"/usr/local/lib/python3.10/site-packages/mage_ai/data_preparation/executors/block_executor.py\", line 1154, in _execute\n    result = self.block.execute_sync(\n  File \"/usr/local/lib/python3.10/site-packages/mage_ai/data_preparation/models/block/__init__.py\", line 1691, in execute_sync\n    return __execute()\n  File \"/usr/local/lib/python3.10/site-packages/mage_ai/data_preparation/models/block/__init__.py\", line 1668, in __execute\n    raise err\n  File \"/usr/local/lib/python3.10/site-packages/mage_ai/data_preparation/models/block/__init__.py\", line 1570, in __execute\n    output = self.execute_block(\n  File \"/usr/local/lib/python3.10/site-packages/mage_ai/data_preparation/models/block/__init__.py\", line 1910, in execute_block\n    outputs = self._execute_block(\n  File \"/usr/local/lib/python3.10/site-packages/mage_ai/data_preparation/models/block/__init__.py\", line 2041, in _execute_block\n    exec(self.content, results)\n  File \"<string>\", line 5, in <module>\nModuleNotFoundError: No module named 'opendatasets'\n", "error_stack": ["  File \"/usr/local/bin/mage\", line 8, in <module>\n    sys.exit(app())\n", "  File \"/usr/local/lib/python3.10/site-packages/typer/main.py\", line 311, in __call__\n    return get_command(self)(*args, **kwargs)\n", "  File \"/usr/local/lib/python3.10/site-packages/click/core.py\", line 1130, in __call__\n    return self.main(*args, **kwargs)\n", "  File \"/usr/local/lib/python3.10/site-packages/typer/core.py\", line 778, in main\n    return _main(\n", "  File \"/usr/local/lib/python3.10/site-packages/typer/core.py\", line 216, in _main\n    rv = self.invoke(ctx)\n", "  File \"/usr/local/lib/python3.10/site-packages/click/core.py\", line 1657, in invoke\n    return _process_result(sub_ctx.command.invoke(sub_ctx))\n", "  File \"/usr/local/lib/python3.10/site-packages/click/core.py\", line 1404, in invoke\n    return ctx.invoke(self.callback, **ctx.params)\n", "  File \"/usr/local/lib/python3.10/site-packages/click/core.py\", line 760, in invoke\n    return __callback(*args, **kwargs)\n", "  File \"/usr/local/lib/python3.10/site-packages/typer/main.py\", line 683, in wrapper\n    return callback(**use_params)  # type: ignore\n", "  File \"/usr/local/lib/python3.10/site-packages/mage_ai/cli/main.py\", line 147, in start\n    start_server(\n", "  File \"/usr/local/lib/python3.10/site-packages/mage_ai/server/server.py\", line 809, in start_server\n    scheduler_manager.start_scheduler()\n", "  File \"/usr/local/lib/python3.10/site-packages/mage_ai/server/scheduler_manager.py\", line 106, in start_scheduler\n    proc.start()\n", "  File \"/usr/local/lib/python3.10/multiprocessing/process.py\", line 121, in start\n    self._popen = self._Popen(self)\n", "  File \"/usr/local/lib/python3.10/multiprocessing/context.py\", line 224, in _Popen\n    return _default_context.get_context().Process._Popen(process_obj)\n", "  File \"/usr/local/lib/python3.10/multiprocessing/context.py\", line 281, in _Popen\n    return Popen(process_obj)\n", "  File \"/usr/local/lib/python3.10/multiprocessing/popen_fork.py\", line 19, in __init__\n    self._launch(process_obj)\n", "  File \"/usr/local/lib/python3.10/multiprocessing/popen_fork.py\", line 71, in _launch\n    code = process_obj._bootstrap(parent_sentinel=child_r)\n", "  File \"/usr/local/lib/python3.10/multiprocessing/process.py\", line 314, in _bootstrap\n    self.run()\n", "  File \"/usr/local/lib/python3.10/multiprocessing/process.py\", line 108, in run\n    self._target(*self._args, **self._kwargs)\n", "  File \"/usr/local/lib/python3.10/site-packages/mage_ai/orchestration/db/process.py\", line 15, in start_session_and_run\n    results = target(*args)\n", "  File \"/usr/local/lib/python3.10/site-packages/mage_ai/server/scheduler_manager.py\", line 58, in run_scheduler\n    LoopTimeTrigger().start()\n", "  File \"/usr/local/lib/python3.10/site-packages/mage_ai/orchestration/triggers/loop_time_trigger.py\", line 14, in start\n    self.run()\n", "  File \"/usr/local/lib/python3.10/site-packages/mage_ai/orchestration/triggers/time_trigger.py\", line 11, in run\n    schedule_all()\n", "  File \"/usr/local/lib/python3.10/site-packages/mage_ai/orchestration/pipeline_scheduler_original.py\", line 1702, in schedule_all\n    PipelineScheduler(r).start()\n", "  File \"/usr/local/lib/python3.10/site-packages/mage_ai/orchestration/db/__init__.py\", line 158, in func_with_rollback\n    return func(*args, **kwargs)\n", "  File \"/usr/local/lib/python3.10/site-packages/mage_ai/orchestration/pipeline_scheduler_original.py\", line 197, in start\n    self.schedule()\n", "  File \"/usr/local/lib/python3.10/site-packages/mage_ai/orchestration/db/__init__.py\", line 158, in func_with_rollback\n    return func(*args, **kwargs)\n", "  File \"/usr/local/lib/python3.10/site-packages/mage_ai/orchestration/pipeline_scheduler_original.py\", line 333, in schedule\n    self.__schedule_blocks(block_runs)\n", "  File \"/usr/local/lib/python3.10/site-packages/mage_ai/orchestration/pipeline_scheduler_original.py\", line 640, in __schedule_blocks\n    job_manager.add_job(\n", "  File \"/usr/local/lib/python3.10/site-packages/mage_ai/orchestration/job_manager.py\", line 20, in add_job\n    self.queue.enqueue(job_id, target, *args, **kwargs)\n", "  File \"/usr/local/lib/python3.10/site-packages/mage_ai/orchestration/queue/process_queue.py\", line 121, in enqueue\n    self.start_worker_pool()\n", "  File \"/usr/local/lib/python3.10/site-packages/mage_ai/orchestration/queue/process_queue.py\", line 198, in start_worker_pool\n    self.worker_pool_proc.start()\n", "  File \"/usr/local/lib/python3.10/multiprocessing/process.py\", line 121, in start\n    self._popen = self._Popen(self)\n", "  File \"/usr/local/lib/python3.10/multiprocessing/context.py\", line 224, in _Popen\n    return _default_context.get_context().Process._Popen(process_obj)\n", "  File \"/usr/local/lib/python3.10/multiprocessing/context.py\", line 281, in _Popen\n    return Popen(process_obj)\n", "  File \"/usr/local/lib/python3.10/multiprocessing/popen_fork.py\", line 19, in __init__\n    self._launch(process_obj)\n", "  File \"/usr/local/lib/python3.10/multiprocessing/popen_fork.py\", line 71, in _launch\n    code = process_obj._bootstrap(parent_sentinel=child_r)\n", "  File \"/usr/local/lib/python3.10/multiprocessing/process.py\", line 314, in _bootstrap\n    self.run()\n", "  File \"/usr/local/lib/python3.10/multiprocessing/process.py\", line 108, in run\n    self._target(*self._args, **self._kwargs)\n", "  File \"/usr/local/lib/python3.10/site-packages/mage_ai/orchestration/queue/process_queue.py\", line 351, in poll_job_and_execute\n    worker.start()\n", "  File \"/usr/local/lib/python3.10/multiprocessing/process.py\", line 121, in start\n    self._popen = self._Popen(self)\n", "  File \"/usr/local/lib/python3.10/multiprocessing/context.py\", line 224, in _Popen\n    return _default_context.get_context().Process._Popen(process_obj)\n", "  File \"/usr/local/lib/python3.10/multiprocessing/context.py\", line 281, in _Popen\n    return Popen(process_obj)\n", "  File \"/usr/local/lib/python3.10/multiprocessing/popen_fork.py\", line 19, in __init__\n    self._launch(process_obj)\n", "  File \"/usr/local/lib/python3.10/multiprocessing/popen_fork.py\", line 71, in _launch\n    code = process_obj._bootstrap(parent_sentinel=child_r)\n", "  File \"/usr/local/lib/python3.10/multiprocessing/process.py\", line 314, in _bootstrap\n    self.run()\n", "  File \"/usr/local/lib/python3.10/site-packages/newrelic/api/background_task.py\", line 117, in wrapper\n    return wrapped(*args, **kwargs)\n", "  File \"/usr/local/lib/python3.10/site-packages/mage_ai/orchestration/queue/process_queue.py\", line 315, in run\n    start_session_and_run(args[1], *args[2], **args[3])\n", "  File \"/usr/local/lib/python3.10/site-packages/mage_ai/orchestration/db/process.py\", line 15, in start_session_and_run\n    results = target(*args)\n", "  File \"/usr/local/lib/python3.10/site-packages/mage_ai/orchestration/pipeline_scheduler_original.py\", line 1235, in run_block\n    return ExecutorFactory.get_block_executor(\n", "  File \"/usr/local/lib/python3.10/site-packages/mage_ai/data_preparation/executors/block_executor.py\", line 647, in execute\n    result = __execute_with_retry()\n", "  File \"/usr/local/lib/python3.10/site-packages/mage_ai/shared/retry.py\", line 46, in retry_func\n    logger.warning(\n", "  File \"/usr/local/lib/python3.10/site-packages/mage_ai/data_preparation/logging/logger.py\", line 39, in warning\n    self.__send_message('warning', message, **kwargs)\n", "  File \"/usr/local/lib/python3.10/site-packages/mage_ai/data_preparation/logging/logger.py\", line 65, in __send_message\n    data['error_stack'] = traceback.format_stack()\n"], "error_stacktrace": "No module named 'opendatasets'"}
2025-02-07T17:26:41 {"block_run_id": 174, "block_uuid": "loading_data", "pipeline_run_id": 19, "pipeline_schedule_id": 1, "pipeline_uuid": "training_models", "hostname": "58c38f4dbaa8", "block_type": "data_loader", "level": "EXCEPTION", "message": "Failed to execute block loading_data", "timestamp": 1738949201.079764, "uuid": "61bfe4f4d2d042c0b067dce79662a4bb", "error": "Traceback (most recent call last):\n  File \"/usr/local/lib/python3.10/site-packages/mage_ai/data_preparation/executors/block_executor.py\", line 647, in execute\n    result = __execute_with_retry()\n  File \"/usr/local/lib/python3.10/site-packages/mage_ai/shared/retry.py\", line 54, in retry_func\n    raise e\n  File \"/usr/local/lib/python3.10/site-packages/mage_ai/shared/retry.py\", line 38, in retry_func\n    return func(*args, **kwargs)\n  File \"/usr/local/lib/python3.10/site-packages/mage_ai/data_preparation/executors/block_executor.py\", line 621, in __execute_with_retry\n    return self._execute(\n  File \"/usr/local/lib/python3.10/site-packages/mage_ai/data_preparation/executors/block_executor.py\", line 1154, in _execute\n    result = self.block.execute_sync(\n  File \"/usr/local/lib/python3.10/site-packages/mage_ai/data_preparation/models/block/__init__.py\", line 1691, in execute_sync\n    return __execute()\n  File \"/usr/local/lib/python3.10/site-packages/mage_ai/data_preparation/models/block/__init__.py\", line 1668, in __execute\n    raise err\n  File \"/usr/local/lib/python3.10/site-packages/mage_ai/data_preparation/models/block/__init__.py\", line 1570, in __execute\n    output = self.execute_block(\n  File \"/usr/local/lib/python3.10/site-packages/mage_ai/data_preparation/models/block/__init__.py\", line 1910, in execute_block\n    outputs = self._execute_block(\n  File \"/usr/local/lib/python3.10/site-packages/mage_ai/data_preparation/models/block/__init__.py\", line 2041, in _execute_block\n    exec(self.content, results)\n  File \"<string>\", line 5, in <module>\nModuleNotFoundError: No module named 'opendatasets'\n", "error_stack": ["  File \"/usr/local/bin/mage\", line 8, in <module>\n    sys.exit(app())\n", "  File \"/usr/local/lib/python3.10/site-packages/typer/main.py\", line 311, in __call__\n    return get_command(self)(*args, **kwargs)\n", "  File \"/usr/local/lib/python3.10/site-packages/click/core.py\", line 1130, in __call__\n    return self.main(*args, **kwargs)\n", "  File \"/usr/local/lib/python3.10/site-packages/typer/core.py\", line 778, in main\n    return _main(\n", "  File \"/usr/local/lib/python3.10/site-packages/typer/core.py\", line 216, in _main\n    rv = self.invoke(ctx)\n", "  File \"/usr/local/lib/python3.10/site-packages/click/core.py\", line 1657, in invoke\n    return _process_result(sub_ctx.command.invoke(sub_ctx))\n", "  File \"/usr/local/lib/python3.10/site-packages/click/core.py\", line 1404, in invoke\n    return ctx.invoke(self.callback, **ctx.params)\n", "  File \"/usr/local/lib/python3.10/site-packages/click/core.py\", line 760, in invoke\n    return __callback(*args, **kwargs)\n", "  File \"/usr/local/lib/python3.10/site-packages/typer/main.py\", line 683, in wrapper\n    return callback(**use_params)  # type: ignore\n", "  File \"/usr/local/lib/python3.10/site-packages/mage_ai/cli/main.py\", line 147, in start\n    start_server(\n", "  File \"/usr/local/lib/python3.10/site-packages/mage_ai/server/server.py\", line 809, in start_server\n    scheduler_manager.start_scheduler()\n", "  File \"/usr/local/lib/python3.10/site-packages/mage_ai/server/scheduler_manager.py\", line 106, in start_scheduler\n    proc.start()\n", "  File \"/usr/local/lib/python3.10/multiprocessing/process.py\", line 121, in start\n    self._popen = self._Popen(self)\n", "  File \"/usr/local/lib/python3.10/multiprocessing/context.py\", line 224, in _Popen\n    return _default_context.get_context().Process._Popen(process_obj)\n", "  File \"/usr/local/lib/python3.10/multiprocessing/context.py\", line 281, in _Popen\n    return Popen(process_obj)\n", "  File \"/usr/local/lib/python3.10/multiprocessing/popen_fork.py\", line 19, in __init__\n    self._launch(process_obj)\n", "  File \"/usr/local/lib/python3.10/multiprocessing/popen_fork.py\", line 71, in _launch\n    code = process_obj._bootstrap(parent_sentinel=child_r)\n", "  File \"/usr/local/lib/python3.10/multiprocessing/process.py\", line 314, in _bootstrap\n    self.run()\n", "  File \"/usr/local/lib/python3.10/multiprocessing/process.py\", line 108, in run\n    self._target(*self._args, **self._kwargs)\n", "  File \"/usr/local/lib/python3.10/site-packages/mage_ai/orchestration/db/process.py\", line 15, in start_session_and_run\n    results = target(*args)\n", "  File \"/usr/local/lib/python3.10/site-packages/mage_ai/server/scheduler_manager.py\", line 58, in run_scheduler\n    LoopTimeTrigger().start()\n", "  File \"/usr/local/lib/python3.10/site-packages/mage_ai/orchestration/triggers/loop_time_trigger.py\", line 14, in start\n    self.run()\n", "  File \"/usr/local/lib/python3.10/site-packages/mage_ai/orchestration/triggers/time_trigger.py\", line 11, in run\n    schedule_all()\n", "  File \"/usr/local/lib/python3.10/site-packages/mage_ai/orchestration/pipeline_scheduler_original.py\", line 1702, in schedule_all\n    PipelineScheduler(r).start()\n", "  File \"/usr/local/lib/python3.10/site-packages/mage_ai/orchestration/db/__init__.py\", line 158, in func_with_rollback\n    return func(*args, **kwargs)\n", "  File \"/usr/local/lib/python3.10/site-packages/mage_ai/orchestration/pipeline_scheduler_original.py\", line 197, in start\n    self.schedule()\n", "  File \"/usr/local/lib/python3.10/site-packages/mage_ai/orchestration/db/__init__.py\", line 158, in func_with_rollback\n    return func(*args, **kwargs)\n", "  File \"/usr/local/lib/python3.10/site-packages/mage_ai/orchestration/pipeline_scheduler_original.py\", line 333, in schedule\n    self.__schedule_blocks(block_runs)\n", "  File \"/usr/local/lib/python3.10/site-packages/mage_ai/orchestration/pipeline_scheduler_original.py\", line 640, in __schedule_blocks\n    job_manager.add_job(\n", "  File \"/usr/local/lib/python3.10/site-packages/mage_ai/orchestration/job_manager.py\", line 20, in add_job\n    self.queue.enqueue(job_id, target, *args, **kwargs)\n", "  File \"/usr/local/lib/python3.10/site-packages/mage_ai/orchestration/queue/process_queue.py\", line 121, in enqueue\n    self.start_worker_pool()\n", "  File \"/usr/local/lib/python3.10/site-packages/mage_ai/orchestration/queue/process_queue.py\", line 198, in start_worker_pool\n    self.worker_pool_proc.start()\n", "  File \"/usr/local/lib/python3.10/multiprocessing/process.py\", line 121, in start\n    self._popen = self._Popen(self)\n", "  File \"/usr/local/lib/python3.10/multiprocessing/context.py\", line 224, in _Popen\n    return _default_context.get_context().Process._Popen(process_obj)\n", "  File \"/usr/local/lib/python3.10/multiprocessing/context.py\", line 281, in _Popen\n    return Popen(process_obj)\n", "  File \"/usr/local/lib/python3.10/multiprocessing/popen_fork.py\", line 19, in __init__\n    self._launch(process_obj)\n", "  File \"/usr/local/lib/python3.10/multiprocessing/popen_fork.py\", line 71, in _launch\n    code = process_obj._bootstrap(parent_sentinel=child_r)\n", "  File \"/usr/local/lib/python3.10/multiprocessing/process.py\", line 314, in _bootstrap\n    self.run()\n", "  File \"/usr/local/lib/python3.10/multiprocessing/process.py\", line 108, in run\n    self._target(*self._args, **self._kwargs)\n", "  File \"/usr/local/lib/python3.10/site-packages/mage_ai/orchestration/queue/process_queue.py\", line 351, in poll_job_and_execute\n    worker.start()\n", "  File \"/usr/local/lib/python3.10/multiprocessing/process.py\", line 121, in start\n    self._popen = self._Popen(self)\n", "  File \"/usr/local/lib/python3.10/multiprocessing/context.py\", line 224, in _Popen\n    return _default_context.get_context().Process._Popen(process_obj)\n", "  File \"/usr/local/lib/python3.10/multiprocessing/context.py\", line 281, in _Popen\n    return Popen(process_obj)\n", "  File \"/usr/local/lib/python3.10/multiprocessing/popen_fork.py\", line 19, in __init__\n    self._launch(process_obj)\n", "  File \"/usr/local/lib/python3.10/multiprocessing/popen_fork.py\", line 71, in _launch\n    code = process_obj._bootstrap(parent_sentinel=child_r)\n", "  File \"/usr/local/lib/python3.10/multiprocessing/process.py\", line 314, in _bootstrap\n    self.run()\n", "  File \"/usr/local/lib/python3.10/site-packages/newrelic/api/background_task.py\", line 117, in wrapper\n    return wrapped(*args, **kwargs)\n", "  File \"/usr/local/lib/python3.10/site-packages/mage_ai/orchestration/queue/process_queue.py\", line 315, in run\n    start_session_and_run(args[1], *args[2], **args[3])\n", "  File \"/usr/local/lib/python3.10/site-packages/mage_ai/orchestration/db/process.py\", line 15, in start_session_and_run\n    results = target(*args)\n", "  File \"/usr/local/lib/python3.10/site-packages/mage_ai/orchestration/pipeline_scheduler_original.py\", line 1235, in run_block\n    return ExecutorFactory.get_block_executor(\n", "  File \"/usr/local/lib/python3.10/site-packages/mage_ai/data_preparation/executors/block_executor.py\", line 649, in execute\n    self.logger.exception(\n", "  File \"/usr/local/lib/python3.10/site-packages/mage_ai/data_preparation/logging/logger.py\", line 30, in exception\n    self.__send_message('exception', message, **kwargs)\n", "  File \"/usr/local/lib/python3.10/site-packages/mage_ai/data_preparation/logging/logger.py\", line 65, in __send_message\n    data['error_stack'] = traceback.format_stack()\n"], "error_stacktrace": "No module named 'opendatasets'"}
Traceback (most recent call last):
  File "/usr/local/lib/python3.10/site-packages/mage_ai/data_preparation/executors/block_executor.py", line 647, in execute
    result = __execute_with_retry()
  File "/usr/local/lib/python3.10/site-packages/mage_ai/shared/retry.py", line 54, in retry_func
    raise e
  File "/usr/local/lib/python3.10/site-packages/mage_ai/shared/retry.py", line 38, in retry_func
    return func(*args, **kwargs)
  File "/usr/local/lib/python3.10/site-packages/mage_ai/data_preparation/executors/block_executor.py", line 621, in __execute_with_retry
    return self._execute(
  File "/usr/local/lib/python3.10/site-packages/mage_ai/data_preparation/executors/block_executor.py", line 1154, in _execute
    result = self.block.execute_sync(
  File "/usr/local/lib/python3.10/site-packages/mage_ai/data_preparation/models/block/__init__.py", line 1691, in execute_sync
    return __execute()
  File "/usr/local/lib/python3.10/site-packages/mage_ai/data_preparation/models/block/__init__.py", line 1668, in __execute
    raise err
  File "/usr/local/lib/python3.10/site-packages/mage_ai/data_preparation/models/block/__init__.py", line 1570, in __execute
    output = self.execute_block(
  File "/usr/local/lib/python3.10/site-packages/mage_ai/data_preparation/models/block/__init__.py", line 1910, in execute_block
    outputs = self._execute_block(
  File "/usr/local/lib/python3.10/site-packages/mage_ai/data_preparation/models/block/__init__.py", line 2041, in _execute_block
    exec(self.content, results)
  File "<string>", line 5, in <module>
ModuleNotFoundError: No module named 'opendatasets'
2025-02-07T17:27:10 {"block_run_id": 184, "block_uuid": "loading_data", "pipeline_run_id": 20, "pipeline_schedule_id": 1, "pipeline_uuid": "training_models", "hostname": "58c38f4dbaa8", "block_type": "data_loader", "level": "INFO", "message": "Start executing block with BlockExecutor.", "timestamp": 1738949230.392645, "uuid": "90a55ac2dbfa40ada32f5ef74cbb7edb"}
2025-02-07T17:27:10 {"block_run_id": 184, "block_uuid": "loading_data", "pipeline_run_id": 20, "pipeline_schedule_id": 1, "pipeline_uuid": "training_models", "hostname": "58c38f4dbaa8", "block_type": "data_loader", "level": "WARNING", "message": "Exception thrown when attempting to run <function BlockExecutor.execute.<locals>.__execute_with_retry at 0x7fc25e1765f0>, attempt 1 of 1", "timestamp": 1738949230.407763, "uuid": "7902953dc6924a208845547cfb7e6eb8", "error": "Traceback (most recent call last):\n  File \"/usr/local/lib/python3.10/site-packages/mage_ai/shared/retry.py\", line 38, in retry_func\n    return func(*args, **kwargs)\n  File \"/usr/local/lib/python3.10/site-packages/mage_ai/data_preparation/executors/block_executor.py\", line 621, in __execute_with_retry\n    return self._execute(\n  File \"/usr/local/lib/python3.10/site-packages/mage_ai/data_preparation/executors/block_executor.py\", line 1154, in _execute\n    result = self.block.execute_sync(\n  File \"/usr/local/lib/python3.10/site-packages/mage_ai/data_preparation/models/block/__init__.py\", line 1691, in execute_sync\n    return __execute()\n  File \"/usr/local/lib/python3.10/site-packages/mage_ai/data_preparation/models/block/__init__.py\", line 1668, in __execute\n    raise err\n  File \"/usr/local/lib/python3.10/site-packages/mage_ai/data_preparation/models/block/__init__.py\", line 1570, in __execute\n    output = self.execute_block(\n  File \"/usr/local/lib/python3.10/site-packages/mage_ai/data_preparation/models/block/__init__.py\", line 1910, in execute_block\n    outputs = self._execute_block(\n  File \"/usr/local/lib/python3.10/site-packages/mage_ai/data_preparation/models/block/__init__.py\", line 2041, in _execute_block\n    exec(self.content, results)\n  File \"<string>\", line 5, in <module>\nModuleNotFoundError: No module named 'opendatasets'\n", "error_stack": ["  File \"/usr/local/bin/mage\", line 8, in <module>\n    sys.exit(app())\n", "  File \"/usr/local/lib/python3.10/site-packages/typer/main.py\", line 311, in __call__\n    return get_command(self)(*args, **kwargs)\n", "  File \"/usr/local/lib/python3.10/site-packages/click/core.py\", line 1130, in __call__\n    return self.main(*args, **kwargs)\n", "  File \"/usr/local/lib/python3.10/site-packages/typer/core.py\", line 778, in main\n    return _main(\n", "  File \"/usr/local/lib/python3.10/site-packages/typer/core.py\", line 216, in _main\n    rv = self.invoke(ctx)\n", "  File \"/usr/local/lib/python3.10/site-packages/click/core.py\", line 1657, in invoke\n    return _process_result(sub_ctx.command.invoke(sub_ctx))\n", "  File \"/usr/local/lib/python3.10/site-packages/click/core.py\", line 1404, in invoke\n    return ctx.invoke(self.callback, **ctx.params)\n", "  File \"/usr/local/lib/python3.10/site-packages/click/core.py\", line 760, in invoke\n    return __callback(*args, **kwargs)\n", "  File \"/usr/local/lib/python3.10/site-packages/typer/main.py\", line 683, in wrapper\n    return callback(**use_params)  # type: ignore\n", "  File \"/usr/local/lib/python3.10/site-packages/mage_ai/cli/main.py\", line 147, in start\n    start_server(\n", "  File \"/usr/local/lib/python3.10/site-packages/mage_ai/server/server.py\", line 809, in start_server\n    scheduler_manager.start_scheduler()\n", "  File \"/usr/local/lib/python3.10/site-packages/mage_ai/server/scheduler_manager.py\", line 106, in start_scheduler\n    proc.start()\n", "  File \"/usr/local/lib/python3.10/multiprocessing/process.py\", line 121, in start\n    self._popen = self._Popen(self)\n", "  File \"/usr/local/lib/python3.10/multiprocessing/context.py\", line 224, in _Popen\n    return _default_context.get_context().Process._Popen(process_obj)\n", "  File \"/usr/local/lib/python3.10/multiprocessing/context.py\", line 281, in _Popen\n    return Popen(process_obj)\n", "  File \"/usr/local/lib/python3.10/multiprocessing/popen_fork.py\", line 19, in __init__\n    self._launch(process_obj)\n", "  File \"/usr/local/lib/python3.10/multiprocessing/popen_fork.py\", line 71, in _launch\n    code = process_obj._bootstrap(parent_sentinel=child_r)\n", "  File \"/usr/local/lib/python3.10/multiprocessing/process.py\", line 314, in _bootstrap\n    self.run()\n", "  File \"/usr/local/lib/python3.10/multiprocessing/process.py\", line 108, in run\n    self._target(*self._args, **self._kwargs)\n", "  File \"/usr/local/lib/python3.10/site-packages/mage_ai/orchestration/db/process.py\", line 15, in start_session_and_run\n    results = target(*args)\n", "  File \"/usr/local/lib/python3.10/site-packages/mage_ai/server/scheduler_manager.py\", line 58, in run_scheduler\n    LoopTimeTrigger().start()\n", "  File \"/usr/local/lib/python3.10/site-packages/mage_ai/orchestration/triggers/loop_time_trigger.py\", line 14, in start\n    self.run()\n", "  File \"/usr/local/lib/python3.10/site-packages/mage_ai/orchestration/triggers/time_trigger.py\", line 11, in run\n    schedule_all()\n", "  File \"/usr/local/lib/python3.10/site-packages/mage_ai/orchestration/pipeline_scheduler_original.py\", line 1702, in schedule_all\n    PipelineScheduler(r).start()\n", "  File \"/usr/local/lib/python3.10/site-packages/mage_ai/orchestration/db/__init__.py\", line 158, in func_with_rollback\n    return func(*args, **kwargs)\n", "  File \"/usr/local/lib/python3.10/site-packages/mage_ai/orchestration/pipeline_scheduler_original.py\", line 197, in start\n    self.schedule()\n", "  File \"/usr/local/lib/python3.10/site-packages/mage_ai/orchestration/db/__init__.py\", line 158, in func_with_rollback\n    return func(*args, **kwargs)\n", "  File \"/usr/local/lib/python3.10/site-packages/mage_ai/orchestration/pipeline_scheduler_original.py\", line 333, in schedule\n    self.__schedule_blocks(block_runs)\n", "  File \"/usr/local/lib/python3.10/site-packages/mage_ai/orchestration/pipeline_scheduler_original.py\", line 640, in __schedule_blocks\n    job_manager.add_job(\n", "  File \"/usr/local/lib/python3.10/site-packages/mage_ai/orchestration/job_manager.py\", line 20, in add_job\n    self.queue.enqueue(job_id, target, *args, **kwargs)\n", "  File \"/usr/local/lib/python3.10/site-packages/mage_ai/orchestration/queue/process_queue.py\", line 121, in enqueue\n    self.start_worker_pool()\n", "  File \"/usr/local/lib/python3.10/site-packages/mage_ai/orchestration/queue/process_queue.py\", line 198, in start_worker_pool\n    self.worker_pool_proc.start()\n", "  File \"/usr/local/lib/python3.10/multiprocessing/process.py\", line 121, in start\n    self._popen = self._Popen(self)\n", "  File \"/usr/local/lib/python3.10/multiprocessing/context.py\", line 224, in _Popen\n    return _default_context.get_context().Process._Popen(process_obj)\n", "  File \"/usr/local/lib/python3.10/multiprocessing/context.py\", line 281, in _Popen\n    return Popen(process_obj)\n", "  File \"/usr/local/lib/python3.10/multiprocessing/popen_fork.py\", line 19, in __init__\n    self._launch(process_obj)\n", "  File \"/usr/local/lib/python3.10/multiprocessing/popen_fork.py\", line 71, in _launch\n    code = process_obj._bootstrap(parent_sentinel=child_r)\n", "  File \"/usr/local/lib/python3.10/multiprocessing/process.py\", line 314, in _bootstrap\n    self.run()\n", "  File \"/usr/local/lib/python3.10/multiprocessing/process.py\", line 108, in run\n    self._target(*self._args, **self._kwargs)\n", "  File \"/usr/local/lib/python3.10/site-packages/mage_ai/orchestration/queue/process_queue.py\", line 351, in poll_job_and_execute\n    worker.start()\n", "  File \"/usr/local/lib/python3.10/multiprocessing/process.py\", line 121, in start\n    self._popen = self._Popen(self)\n", "  File \"/usr/local/lib/python3.10/multiprocessing/context.py\", line 224, in _Popen\n    return _default_context.get_context().Process._Popen(process_obj)\n", "  File \"/usr/local/lib/python3.10/multiprocessing/context.py\", line 281, in _Popen\n    return Popen(process_obj)\n", "  File \"/usr/local/lib/python3.10/multiprocessing/popen_fork.py\", line 19, in __init__\n    self._launch(process_obj)\n", "  File \"/usr/local/lib/python3.10/multiprocessing/popen_fork.py\", line 71, in _launch\n    code = process_obj._bootstrap(parent_sentinel=child_r)\n", "  File \"/usr/local/lib/python3.10/multiprocessing/process.py\", line 314, in _bootstrap\n    self.run()\n", "  File \"/usr/local/lib/python3.10/site-packages/newrelic/api/background_task.py\", line 117, in wrapper\n    return wrapped(*args, **kwargs)\n", "  File \"/usr/local/lib/python3.10/site-packages/mage_ai/orchestration/queue/process_queue.py\", line 315, in run\n    start_session_and_run(args[1], *args[2], **args[3])\n", "  File \"/usr/local/lib/python3.10/site-packages/mage_ai/orchestration/db/process.py\", line 15, in start_session_and_run\n    results = target(*args)\n", "  File \"/usr/local/lib/python3.10/site-packages/mage_ai/orchestration/pipeline_scheduler_original.py\", line 1235, in run_block\n    return ExecutorFactory.get_block_executor(\n", "  File \"/usr/local/lib/python3.10/site-packages/mage_ai/data_preparation/executors/block_executor.py\", line 647, in execute\n    result = __execute_with_retry()\n", "  File \"/usr/local/lib/python3.10/site-packages/mage_ai/shared/retry.py\", line 46, in retry_func\n    logger.warning(\n", "  File \"/usr/local/lib/python3.10/site-packages/mage_ai/data_preparation/logging/logger.py\", line 39, in warning\n    self.__send_message('warning', message, **kwargs)\n", "  File \"/usr/local/lib/python3.10/site-packages/mage_ai/data_preparation/logging/logger.py\", line 65, in __send_message\n    data['error_stack'] = traceback.format_stack()\n"], "error_stacktrace": "No module named 'opendatasets'"}
2025-02-07T17:27:10 {"block_run_id": 184, "block_uuid": "loading_data", "pipeline_run_id": 20, "pipeline_schedule_id": 1, "pipeline_uuid": "training_models", "hostname": "58c38f4dbaa8", "block_type": "data_loader", "level": "EXCEPTION", "message": "Failed to execute block loading_data", "timestamp": 1738949230.410685, "uuid": "a30b2283bd9f4a2f83f657995efb11fe", "error": "Traceback (most recent call last):\n  File \"/usr/local/lib/python3.10/site-packages/mage_ai/data_preparation/executors/block_executor.py\", line 647, in execute\n    result = __execute_with_retry()\n  File \"/usr/local/lib/python3.10/site-packages/mage_ai/shared/retry.py\", line 54, in retry_func\n    raise e\n  File \"/usr/local/lib/python3.10/site-packages/mage_ai/shared/retry.py\", line 38, in retry_func\n    return func(*args, **kwargs)\n  File \"/usr/local/lib/python3.10/site-packages/mage_ai/data_preparation/executors/block_executor.py\", line 621, in __execute_with_retry\n    return self._execute(\n  File \"/usr/local/lib/python3.10/site-packages/mage_ai/data_preparation/executors/block_executor.py\", line 1154, in _execute\n    result = self.block.execute_sync(\n  File \"/usr/local/lib/python3.10/site-packages/mage_ai/data_preparation/models/block/__init__.py\", line 1691, in execute_sync\n    return __execute()\n  File \"/usr/local/lib/python3.10/site-packages/mage_ai/data_preparation/models/block/__init__.py\", line 1668, in __execute\n    raise err\n  File \"/usr/local/lib/python3.10/site-packages/mage_ai/data_preparation/models/block/__init__.py\", line 1570, in __execute\n    output = self.execute_block(\n  File \"/usr/local/lib/python3.10/site-packages/mage_ai/data_preparation/models/block/__init__.py\", line 1910, in execute_block\n    outputs = self._execute_block(\n  File \"/usr/local/lib/python3.10/site-packages/mage_ai/data_preparation/models/block/__init__.py\", line 2041, in _execute_block\n    exec(self.content, results)\n  File \"<string>\", line 5, in <module>\nModuleNotFoundError: No module named 'opendatasets'\n", "error_stack": ["  File \"/usr/local/bin/mage\", line 8, in <module>\n    sys.exit(app())\n", "  File \"/usr/local/lib/python3.10/site-packages/typer/main.py\", line 311, in __call__\n    return get_command(self)(*args, **kwargs)\n", "  File \"/usr/local/lib/python3.10/site-packages/click/core.py\", line 1130, in __call__\n    return self.main(*args, **kwargs)\n", "  File \"/usr/local/lib/python3.10/site-packages/typer/core.py\", line 778, in main\n    return _main(\n", "  File \"/usr/local/lib/python3.10/site-packages/typer/core.py\", line 216, in _main\n    rv = self.invoke(ctx)\n", "  File \"/usr/local/lib/python3.10/site-packages/click/core.py\", line 1657, in invoke\n    return _process_result(sub_ctx.command.invoke(sub_ctx))\n", "  File \"/usr/local/lib/python3.10/site-packages/click/core.py\", line 1404, in invoke\n    return ctx.invoke(self.callback, **ctx.params)\n", "  File \"/usr/local/lib/python3.10/site-packages/click/core.py\", line 760, in invoke\n    return __callback(*args, **kwargs)\n", "  File \"/usr/local/lib/python3.10/site-packages/typer/main.py\", line 683, in wrapper\n    return callback(**use_params)  # type: ignore\n", "  File \"/usr/local/lib/python3.10/site-packages/mage_ai/cli/main.py\", line 147, in start\n    start_server(\n", "  File \"/usr/local/lib/python3.10/site-packages/mage_ai/server/server.py\", line 809, in start_server\n    scheduler_manager.start_scheduler()\n", "  File \"/usr/local/lib/python3.10/site-packages/mage_ai/server/scheduler_manager.py\", line 106, in start_scheduler\n    proc.start()\n", "  File \"/usr/local/lib/python3.10/multiprocessing/process.py\", line 121, in start\n    self._popen = self._Popen(self)\n", "  File \"/usr/local/lib/python3.10/multiprocessing/context.py\", line 224, in _Popen\n    return _default_context.get_context().Process._Popen(process_obj)\n", "  File \"/usr/local/lib/python3.10/multiprocessing/context.py\", line 281, in _Popen\n    return Popen(process_obj)\n", "  File \"/usr/local/lib/python3.10/multiprocessing/popen_fork.py\", line 19, in __init__\n    self._launch(process_obj)\n", "  File \"/usr/local/lib/python3.10/multiprocessing/popen_fork.py\", line 71, in _launch\n    code = process_obj._bootstrap(parent_sentinel=child_r)\n", "  File \"/usr/local/lib/python3.10/multiprocessing/process.py\", line 314, in _bootstrap\n    self.run()\n", "  File \"/usr/local/lib/python3.10/multiprocessing/process.py\", line 108, in run\n    self._target(*self._args, **self._kwargs)\n", "  File \"/usr/local/lib/python3.10/site-packages/mage_ai/orchestration/db/process.py\", line 15, in start_session_and_run\n    results = target(*args)\n", "  File \"/usr/local/lib/python3.10/site-packages/mage_ai/server/scheduler_manager.py\", line 58, in run_scheduler\n    LoopTimeTrigger().start()\n", "  File \"/usr/local/lib/python3.10/site-packages/mage_ai/orchestration/triggers/loop_time_trigger.py\", line 14, in start\n    self.run()\n", "  File \"/usr/local/lib/python3.10/site-packages/mage_ai/orchestration/triggers/time_trigger.py\", line 11, in run\n    schedule_all()\n", "  File \"/usr/local/lib/python3.10/site-packages/mage_ai/orchestration/pipeline_scheduler_original.py\", line 1702, in schedule_all\n    PipelineScheduler(r).start()\n", "  File \"/usr/local/lib/python3.10/site-packages/mage_ai/orchestration/db/__init__.py\", line 158, in func_with_rollback\n    return func(*args, **kwargs)\n", "  File \"/usr/local/lib/python3.10/site-packages/mage_ai/orchestration/pipeline_scheduler_original.py\", line 197, in start\n    self.schedule()\n", "  File \"/usr/local/lib/python3.10/site-packages/mage_ai/orchestration/db/__init__.py\", line 158, in func_with_rollback\n    return func(*args, **kwargs)\n", "  File \"/usr/local/lib/python3.10/site-packages/mage_ai/orchestration/pipeline_scheduler_original.py\", line 333, in schedule\n    self.__schedule_blocks(block_runs)\n", "  File \"/usr/local/lib/python3.10/site-packages/mage_ai/orchestration/pipeline_scheduler_original.py\", line 640, in __schedule_blocks\n    job_manager.add_job(\n", "  File \"/usr/local/lib/python3.10/site-packages/mage_ai/orchestration/job_manager.py\", line 20, in add_job\n    self.queue.enqueue(job_id, target, *args, **kwargs)\n", "  File \"/usr/local/lib/python3.10/site-packages/mage_ai/orchestration/queue/process_queue.py\", line 121, in enqueue\n    self.start_worker_pool()\n", "  File \"/usr/local/lib/python3.10/site-packages/mage_ai/orchestration/queue/process_queue.py\", line 198, in start_worker_pool\n    self.worker_pool_proc.start()\n", "  File \"/usr/local/lib/python3.10/multiprocessing/process.py\", line 121, in start\n    self._popen = self._Popen(self)\n", "  File \"/usr/local/lib/python3.10/multiprocessing/context.py\", line 224, in _Popen\n    return _default_context.get_context().Process._Popen(process_obj)\n", "  File \"/usr/local/lib/python3.10/multiprocessing/context.py\", line 281, in _Popen\n    return Popen(process_obj)\n", "  File \"/usr/local/lib/python3.10/multiprocessing/popen_fork.py\", line 19, in __init__\n    self._launch(process_obj)\n", "  File \"/usr/local/lib/python3.10/multiprocessing/popen_fork.py\", line 71, in _launch\n    code = process_obj._bootstrap(parent_sentinel=child_r)\n", "  File \"/usr/local/lib/python3.10/multiprocessing/process.py\", line 314, in _bootstrap\n    self.run()\n", "  File \"/usr/local/lib/python3.10/multiprocessing/process.py\", line 108, in run\n    self._target(*self._args, **self._kwargs)\n", "  File \"/usr/local/lib/python3.10/site-packages/mage_ai/orchestration/queue/process_queue.py\", line 351, in poll_job_and_execute\n    worker.start()\n", "  File \"/usr/local/lib/python3.10/multiprocessing/process.py\", line 121, in start\n    self._popen = self._Popen(self)\n", "  File \"/usr/local/lib/python3.10/multiprocessing/context.py\", line 224, in _Popen\n    return _default_context.get_context().Process._Popen(process_obj)\n", "  File \"/usr/local/lib/python3.10/multiprocessing/context.py\", line 281, in _Popen\n    return Popen(process_obj)\n", "  File \"/usr/local/lib/python3.10/multiprocessing/popen_fork.py\", line 19, in __init__\n    self._launch(process_obj)\n", "  File \"/usr/local/lib/python3.10/multiprocessing/popen_fork.py\", line 71, in _launch\n    code = process_obj._bootstrap(parent_sentinel=child_r)\n", "  File \"/usr/local/lib/python3.10/multiprocessing/process.py\", line 314, in _bootstrap\n    self.run()\n", "  File \"/usr/local/lib/python3.10/site-packages/newrelic/api/background_task.py\", line 117, in wrapper\n    return wrapped(*args, **kwargs)\n", "  File \"/usr/local/lib/python3.10/site-packages/mage_ai/orchestration/queue/process_queue.py\", line 315, in run\n    start_session_and_run(args[1], *args[2], **args[3])\n", "  File \"/usr/local/lib/python3.10/site-packages/mage_ai/orchestration/db/process.py\", line 15, in start_session_and_run\n    results = target(*args)\n", "  File \"/usr/local/lib/python3.10/site-packages/mage_ai/orchestration/pipeline_scheduler_original.py\", line 1235, in run_block\n    return ExecutorFactory.get_block_executor(\n", "  File \"/usr/local/lib/python3.10/site-packages/mage_ai/data_preparation/executors/block_executor.py\", line 649, in execute\n    self.logger.exception(\n", "  File \"/usr/local/lib/python3.10/site-packages/mage_ai/data_preparation/logging/logger.py\", line 30, in exception\n    self.__send_message('exception', message, **kwargs)\n", "  File \"/usr/local/lib/python3.10/site-packages/mage_ai/data_preparation/logging/logger.py\", line 65, in __send_message\n    data['error_stack'] = traceback.format_stack()\n"], "error_stacktrace": "No module named 'opendatasets'"}
Traceback (most recent call last):
  File "/usr/local/lib/python3.10/site-packages/mage_ai/data_preparation/executors/block_executor.py", line 647, in execute
    result = __execute_with_retry()
  File "/usr/local/lib/python3.10/site-packages/mage_ai/shared/retry.py", line 54, in retry_func
    raise e
  File "/usr/local/lib/python3.10/site-packages/mage_ai/shared/retry.py", line 38, in retry_func
    return func(*args, **kwargs)
  File "/usr/local/lib/python3.10/site-packages/mage_ai/data_preparation/executors/block_executor.py", line 621, in __execute_with_retry
    return self._execute(
  File "/usr/local/lib/python3.10/site-packages/mage_ai/data_preparation/executors/block_executor.py", line 1154, in _execute
    result = self.block.execute_sync(
  File "/usr/local/lib/python3.10/site-packages/mage_ai/data_preparation/models/block/__init__.py", line 1691, in execute_sync
    return __execute()
  File "/usr/local/lib/python3.10/site-packages/mage_ai/data_preparation/models/block/__init__.py", line 1668, in __execute
    raise err
  File "/usr/local/lib/python3.10/site-packages/mage_ai/data_preparation/models/block/__init__.py", line 1570, in __execute
    output = self.execute_block(
  File "/usr/local/lib/python3.10/site-packages/mage_ai/data_preparation/models/block/__init__.py", line 1910, in execute_block
    outputs = self._execute_block(
  File "/usr/local/lib/python3.10/site-packages/mage_ai/data_preparation/models/block/__init__.py", line 2041, in _execute_block
    exec(self.content, results)
  File "<string>", line 5, in <module>
ModuleNotFoundError: No module named 'opendatasets'
2025-02-07T17:47:42 {"block_run_id": 194, "block_uuid": "loading_data", "pipeline_run_id": 21, "pipeline_schedule_id": 1, "pipeline_uuid": "training_models", "hostname": "b262786611bb", "block_type": "data_loader", "level": "INFO", "message": "Start executing block with BlockExecutor.", "timestamp": 1738950462.703913, "uuid": "0324a3c2c6714a118f131f8710809604"}
2025-02-07T17:47:42 {"block_run_id": 194, "block_uuid": "loading_data", "pipeline_run_id": 21, "pipeline_schedule_id": 1, "pipeline_uuid": "training_models", "hostname": "b262786611bb", "block_type": "data_loader", "level": "WARNING", "message": "Exception thrown when attempting to run <function BlockExecutor.execute.<locals>.__execute_with_retry at 0x7f581d48a3b0>, attempt 1 of 1", "timestamp": 1738950462.717682, "uuid": "117df341356541c7a006f7a99b397b10", "error": "Traceback (most recent call last):\n  File \"/usr/local/lib/python3.10/site-packages/mage_ai/shared/retry.py\", line 38, in retry_func\n    return func(*args, **kwargs)\n  File \"/usr/local/lib/python3.10/site-packages/mage_ai/data_preparation/executors/block_executor.py\", line 621, in __execute_with_retry\n    return self._execute(\n  File \"/usr/local/lib/python3.10/site-packages/mage_ai/data_preparation/executors/block_executor.py\", line 1154, in _execute\n    result = self.block.execute_sync(\n  File \"/usr/local/lib/python3.10/site-packages/mage_ai/data_preparation/models/block/__init__.py\", line 1691, in execute_sync\n    return __execute()\n  File \"/usr/local/lib/python3.10/site-packages/mage_ai/data_preparation/models/block/__init__.py\", line 1668, in __execute\n    raise err\n  File \"/usr/local/lib/python3.10/site-packages/mage_ai/data_preparation/models/block/__init__.py\", line 1570, in __execute\n    output = self.execute_block(\n  File \"/usr/local/lib/python3.10/site-packages/mage_ai/data_preparation/models/block/__init__.py\", line 1910, in execute_block\n    outputs = self._execute_block(\n  File \"/usr/local/lib/python3.10/site-packages/mage_ai/data_preparation/models/block/__init__.py\", line 2041, in _execute_block\n    exec(self.content, results)\n  File \"<string>\", line 5, in <module>\nModuleNotFoundError: No module named 'opendatasets'\n", "error_stack": ["  File \"/usr/local/bin/mage\", line 8, in <module>\n    sys.exit(app())\n", "  File \"/usr/local/lib/python3.10/site-packages/typer/main.py\", line 311, in __call__\n    return get_command(self)(*args, **kwargs)\n", "  File \"/usr/local/lib/python3.10/site-packages/click/core.py\", line 1130, in __call__\n    return self.main(*args, **kwargs)\n", "  File \"/usr/local/lib/python3.10/site-packages/typer/core.py\", line 778, in main\n    return _main(\n", "  File \"/usr/local/lib/python3.10/site-packages/typer/core.py\", line 216, in _main\n    rv = self.invoke(ctx)\n", "  File \"/usr/local/lib/python3.10/site-packages/click/core.py\", line 1657, in invoke\n    return _process_result(sub_ctx.command.invoke(sub_ctx))\n", "  File \"/usr/local/lib/python3.10/site-packages/click/core.py\", line 1404, in invoke\n    return ctx.invoke(self.callback, **ctx.params)\n", "  File \"/usr/local/lib/python3.10/site-packages/click/core.py\", line 760, in invoke\n    return __callback(*args, **kwargs)\n", "  File \"/usr/local/lib/python3.10/site-packages/typer/main.py\", line 683, in wrapper\n    return callback(**use_params)  # type: ignore\n", "  File \"/usr/local/lib/python3.10/site-packages/mage_ai/cli/main.py\", line 147, in start\n    start_server(\n", "  File \"/usr/local/lib/python3.10/site-packages/mage_ai/server/server.py\", line 809, in start_server\n    scheduler_manager.start_scheduler()\n", "  File \"/usr/local/lib/python3.10/site-packages/mage_ai/server/scheduler_manager.py\", line 106, in start_scheduler\n    proc.start()\n", "  File \"/usr/local/lib/python3.10/multiprocessing/process.py\", line 121, in start\n    self._popen = self._Popen(self)\n", "  File \"/usr/local/lib/python3.10/multiprocessing/context.py\", line 224, in _Popen\n    return _default_context.get_context().Process._Popen(process_obj)\n", "  File \"/usr/local/lib/python3.10/multiprocessing/context.py\", line 281, in _Popen\n    return Popen(process_obj)\n", "  File \"/usr/local/lib/python3.10/multiprocessing/popen_fork.py\", line 19, in __init__\n    self._launch(process_obj)\n", "  File \"/usr/local/lib/python3.10/multiprocessing/popen_fork.py\", line 71, in _launch\n    code = process_obj._bootstrap(parent_sentinel=child_r)\n", "  File \"/usr/local/lib/python3.10/multiprocessing/process.py\", line 314, in _bootstrap\n    self.run()\n", "  File \"/usr/local/lib/python3.10/multiprocessing/process.py\", line 108, in run\n    self._target(*self._args, **self._kwargs)\n", "  File \"/usr/local/lib/python3.10/site-packages/mage_ai/orchestration/db/process.py\", line 15, in start_session_and_run\n    results = target(*args)\n", "  File \"/usr/local/lib/python3.10/site-packages/mage_ai/server/scheduler_manager.py\", line 58, in run_scheduler\n    LoopTimeTrigger().start()\n", "  File \"/usr/local/lib/python3.10/site-packages/mage_ai/orchestration/triggers/loop_time_trigger.py\", line 14, in start\n    self.run()\n", "  File \"/usr/local/lib/python3.10/site-packages/mage_ai/orchestration/triggers/time_trigger.py\", line 11, in run\n    schedule_all()\n", "  File \"/usr/local/lib/python3.10/site-packages/mage_ai/orchestration/pipeline_scheduler_original.py\", line 1702, in schedule_all\n    PipelineScheduler(r).start()\n", "  File \"/usr/local/lib/python3.10/site-packages/mage_ai/orchestration/db/__init__.py\", line 158, in func_with_rollback\n    return func(*args, **kwargs)\n", "  File \"/usr/local/lib/python3.10/site-packages/mage_ai/orchestration/pipeline_scheduler_original.py\", line 197, in start\n    self.schedule()\n", "  File \"/usr/local/lib/python3.10/site-packages/mage_ai/orchestration/db/__init__.py\", line 158, in func_with_rollback\n    return func(*args, **kwargs)\n", "  File \"/usr/local/lib/python3.10/site-packages/mage_ai/orchestration/pipeline_scheduler_original.py\", line 333, in schedule\n    self.__schedule_blocks(block_runs)\n", "  File \"/usr/local/lib/python3.10/site-packages/mage_ai/orchestration/pipeline_scheduler_original.py\", line 640, in __schedule_blocks\n    job_manager.add_job(\n", "  File \"/usr/local/lib/python3.10/site-packages/mage_ai/orchestration/job_manager.py\", line 20, in add_job\n    self.queue.enqueue(job_id, target, *args, **kwargs)\n", "  File \"/usr/local/lib/python3.10/site-packages/mage_ai/orchestration/queue/process_queue.py\", line 121, in enqueue\n    self.start_worker_pool()\n", "  File \"/usr/local/lib/python3.10/site-packages/mage_ai/orchestration/queue/process_queue.py\", line 198, in start_worker_pool\n    self.worker_pool_proc.start()\n", "  File \"/usr/local/lib/python3.10/multiprocessing/process.py\", line 121, in start\n    self._popen = self._Popen(self)\n", "  File \"/usr/local/lib/python3.10/multiprocessing/context.py\", line 224, in _Popen\n    return _default_context.get_context().Process._Popen(process_obj)\n", "  File \"/usr/local/lib/python3.10/multiprocessing/context.py\", line 281, in _Popen\n    return Popen(process_obj)\n", "  File \"/usr/local/lib/python3.10/multiprocessing/popen_fork.py\", line 19, in __init__\n    self._launch(process_obj)\n", "  File \"/usr/local/lib/python3.10/multiprocessing/popen_fork.py\", line 71, in _launch\n    code = process_obj._bootstrap(parent_sentinel=child_r)\n", "  File \"/usr/local/lib/python3.10/multiprocessing/process.py\", line 314, in _bootstrap\n    self.run()\n", "  File \"/usr/local/lib/python3.10/multiprocessing/process.py\", line 108, in run\n    self._target(*self._args, **self._kwargs)\n", "  File \"/usr/local/lib/python3.10/site-packages/mage_ai/orchestration/queue/process_queue.py\", line 351, in poll_job_and_execute\n    worker.start()\n", "  File \"/usr/local/lib/python3.10/multiprocessing/process.py\", line 121, in start\n    self._popen = self._Popen(self)\n", "  File \"/usr/local/lib/python3.10/multiprocessing/context.py\", line 224, in _Popen\n    return _default_context.get_context().Process._Popen(process_obj)\n", "  File \"/usr/local/lib/python3.10/multiprocessing/context.py\", line 281, in _Popen\n    return Popen(process_obj)\n", "  File \"/usr/local/lib/python3.10/multiprocessing/popen_fork.py\", line 19, in __init__\n    self._launch(process_obj)\n", "  File \"/usr/local/lib/python3.10/multiprocessing/popen_fork.py\", line 71, in _launch\n    code = process_obj._bootstrap(parent_sentinel=child_r)\n", "  File \"/usr/local/lib/python3.10/multiprocessing/process.py\", line 314, in _bootstrap\n    self.run()\n", "  File \"/usr/local/lib/python3.10/site-packages/newrelic/api/background_task.py\", line 117, in wrapper\n    return wrapped(*args, **kwargs)\n", "  File \"/usr/local/lib/python3.10/site-packages/mage_ai/orchestration/queue/process_queue.py\", line 315, in run\n    start_session_and_run(args[1], *args[2], **args[3])\n", "  File \"/usr/local/lib/python3.10/site-packages/mage_ai/orchestration/db/process.py\", line 15, in start_session_and_run\n    results = target(*args)\n", "  File \"/usr/local/lib/python3.10/site-packages/mage_ai/orchestration/pipeline_scheduler_original.py\", line 1235, in run_block\n    return ExecutorFactory.get_block_executor(\n", "  File \"/usr/local/lib/python3.10/site-packages/mage_ai/data_preparation/executors/block_executor.py\", line 647, in execute\n    result = __execute_with_retry()\n", "  File \"/usr/local/lib/python3.10/site-packages/mage_ai/shared/retry.py\", line 46, in retry_func\n    logger.warning(\n", "  File \"/usr/local/lib/python3.10/site-packages/mage_ai/data_preparation/logging/logger.py\", line 39, in warning\n    self.__send_message('warning', message, **kwargs)\n", "  File \"/usr/local/lib/python3.10/site-packages/mage_ai/data_preparation/logging/logger.py\", line 65, in __send_message\n    data['error_stack'] = traceback.format_stack()\n"], "error_stacktrace": "No module named 'opendatasets'"}
2025-02-07T17:47:42 {"block_run_id": 194, "block_uuid": "loading_data", "pipeline_run_id": 21, "pipeline_schedule_id": 1, "pipeline_uuid": "training_models", "hostname": "b262786611bb", "block_type": "data_loader", "level": "EXCEPTION", "message": "Failed to execute block loading_data", "timestamp": 1738950462.727413, "uuid": "40b7ab2447ab4403a74988bdabf29c91", "error": "Traceback (most recent call last):\n  File \"/usr/local/lib/python3.10/site-packages/mage_ai/data_preparation/executors/block_executor.py\", line 647, in execute\n    result = __execute_with_retry()\n  File \"/usr/local/lib/python3.10/site-packages/mage_ai/shared/retry.py\", line 54, in retry_func\n    raise e\n  File \"/usr/local/lib/python3.10/site-packages/mage_ai/shared/retry.py\", line 38, in retry_func\n    return func(*args, **kwargs)\n  File \"/usr/local/lib/python3.10/site-packages/mage_ai/data_preparation/executors/block_executor.py\", line 621, in __execute_with_retry\n    return self._execute(\n  File \"/usr/local/lib/python3.10/site-packages/mage_ai/data_preparation/executors/block_executor.py\", line 1154, in _execute\n    result = self.block.execute_sync(\n  File \"/usr/local/lib/python3.10/site-packages/mage_ai/data_preparation/models/block/__init__.py\", line 1691, in execute_sync\n    return __execute()\n  File \"/usr/local/lib/python3.10/site-packages/mage_ai/data_preparation/models/block/__init__.py\", line 1668, in __execute\n    raise err\n  File \"/usr/local/lib/python3.10/site-packages/mage_ai/data_preparation/models/block/__init__.py\", line 1570, in __execute\n    output = self.execute_block(\n  File \"/usr/local/lib/python3.10/site-packages/mage_ai/data_preparation/models/block/__init__.py\", line 1910, in execute_block\n    outputs = self._execute_block(\n  File \"/usr/local/lib/python3.10/site-packages/mage_ai/data_preparation/models/block/__init__.py\", line 2041, in _execute_block\n    exec(self.content, results)\n  File \"<string>\", line 5, in <module>\nModuleNotFoundError: No module named 'opendatasets'\n", "error_stack": ["  File \"/usr/local/bin/mage\", line 8, in <module>\n    sys.exit(app())\n", "  File \"/usr/local/lib/python3.10/site-packages/typer/main.py\", line 311, in __call__\n    return get_command(self)(*args, **kwargs)\n", "  File \"/usr/local/lib/python3.10/site-packages/click/core.py\", line 1130, in __call__\n    return self.main(*args, **kwargs)\n", "  File \"/usr/local/lib/python3.10/site-packages/typer/core.py\", line 778, in main\n    return _main(\n", "  File \"/usr/local/lib/python3.10/site-packages/typer/core.py\", line 216, in _main\n    rv = self.invoke(ctx)\n", "  File \"/usr/local/lib/python3.10/site-packages/click/core.py\", line 1657, in invoke\n    return _process_result(sub_ctx.command.invoke(sub_ctx))\n", "  File \"/usr/local/lib/python3.10/site-packages/click/core.py\", line 1404, in invoke\n    return ctx.invoke(self.callback, **ctx.params)\n", "  File \"/usr/local/lib/python3.10/site-packages/click/core.py\", line 760, in invoke\n    return __callback(*args, **kwargs)\n", "  File \"/usr/local/lib/python3.10/site-packages/typer/main.py\", line 683, in wrapper\n    return callback(**use_params)  # type: ignore\n", "  File \"/usr/local/lib/python3.10/site-packages/mage_ai/cli/main.py\", line 147, in start\n    start_server(\n", "  File \"/usr/local/lib/python3.10/site-packages/mage_ai/server/server.py\", line 809, in start_server\n    scheduler_manager.start_scheduler()\n", "  File \"/usr/local/lib/python3.10/site-packages/mage_ai/server/scheduler_manager.py\", line 106, in start_scheduler\n    proc.start()\n", "  File \"/usr/local/lib/python3.10/multiprocessing/process.py\", line 121, in start\n    self._popen = self._Popen(self)\n", "  File \"/usr/local/lib/python3.10/multiprocessing/context.py\", line 224, in _Popen\n    return _default_context.get_context().Process._Popen(process_obj)\n", "  File \"/usr/local/lib/python3.10/multiprocessing/context.py\", line 281, in _Popen\n    return Popen(process_obj)\n", "  File \"/usr/local/lib/python3.10/multiprocessing/popen_fork.py\", line 19, in __init__\n    self._launch(process_obj)\n", "  File \"/usr/local/lib/python3.10/multiprocessing/popen_fork.py\", line 71, in _launch\n    code = process_obj._bootstrap(parent_sentinel=child_r)\n", "  File \"/usr/local/lib/python3.10/multiprocessing/process.py\", line 314, in _bootstrap\n    self.run()\n", "  File \"/usr/local/lib/python3.10/multiprocessing/process.py\", line 108, in run\n    self._target(*self._args, **self._kwargs)\n", "  File \"/usr/local/lib/python3.10/site-packages/mage_ai/orchestration/db/process.py\", line 15, in start_session_and_run\n    results = target(*args)\n", "  File \"/usr/local/lib/python3.10/site-packages/mage_ai/server/scheduler_manager.py\", line 58, in run_scheduler\n    LoopTimeTrigger().start()\n", "  File \"/usr/local/lib/python3.10/site-packages/mage_ai/orchestration/triggers/loop_time_trigger.py\", line 14, in start\n    self.run()\n", "  File \"/usr/local/lib/python3.10/site-packages/mage_ai/orchestration/triggers/time_trigger.py\", line 11, in run\n    schedule_all()\n", "  File \"/usr/local/lib/python3.10/site-packages/mage_ai/orchestration/pipeline_scheduler_original.py\", line 1702, in schedule_all\n    PipelineScheduler(r).start()\n", "  File \"/usr/local/lib/python3.10/site-packages/mage_ai/orchestration/db/__init__.py\", line 158, in func_with_rollback\n    return func(*args, **kwargs)\n", "  File \"/usr/local/lib/python3.10/site-packages/mage_ai/orchestration/pipeline_scheduler_original.py\", line 197, in start\n    self.schedule()\n", "  File \"/usr/local/lib/python3.10/site-packages/mage_ai/orchestration/db/__init__.py\", line 158, in func_with_rollback\n    return func(*args, **kwargs)\n", "  File \"/usr/local/lib/python3.10/site-packages/mage_ai/orchestration/pipeline_scheduler_original.py\", line 333, in schedule\n    self.__schedule_blocks(block_runs)\n", "  File \"/usr/local/lib/python3.10/site-packages/mage_ai/orchestration/pipeline_scheduler_original.py\", line 640, in __schedule_blocks\n    job_manager.add_job(\n", "  File \"/usr/local/lib/python3.10/site-packages/mage_ai/orchestration/job_manager.py\", line 20, in add_job\n    self.queue.enqueue(job_id, target, *args, **kwargs)\n", "  File \"/usr/local/lib/python3.10/site-packages/mage_ai/orchestration/queue/process_queue.py\", line 121, in enqueue\n    self.start_worker_pool()\n", "  File \"/usr/local/lib/python3.10/site-packages/mage_ai/orchestration/queue/process_queue.py\", line 198, in start_worker_pool\n    self.worker_pool_proc.start()\n", "  File \"/usr/local/lib/python3.10/multiprocessing/process.py\", line 121, in start\n    self._popen = self._Popen(self)\n", "  File \"/usr/local/lib/python3.10/multiprocessing/context.py\", line 224, in _Popen\n    return _default_context.get_context().Process._Popen(process_obj)\n", "  File \"/usr/local/lib/python3.10/multiprocessing/context.py\", line 281, in _Popen\n    return Popen(process_obj)\n", "  File \"/usr/local/lib/python3.10/multiprocessing/popen_fork.py\", line 19, in __init__\n    self._launch(process_obj)\n", "  File \"/usr/local/lib/python3.10/multiprocessing/popen_fork.py\", line 71, in _launch\n    code = process_obj._bootstrap(parent_sentinel=child_r)\n", "  File \"/usr/local/lib/python3.10/multiprocessing/process.py\", line 314, in _bootstrap\n    self.run()\n", "  File \"/usr/local/lib/python3.10/multiprocessing/process.py\", line 108, in run\n    self._target(*self._args, **self._kwargs)\n", "  File \"/usr/local/lib/python3.10/site-packages/mage_ai/orchestration/queue/process_queue.py\", line 351, in poll_job_and_execute\n    worker.start()\n", "  File \"/usr/local/lib/python3.10/multiprocessing/process.py\", line 121, in start\n    self._popen = self._Popen(self)\n", "  File \"/usr/local/lib/python3.10/multiprocessing/context.py\", line 224, in _Popen\n    return _default_context.get_context().Process._Popen(process_obj)\n", "  File \"/usr/local/lib/python3.10/multiprocessing/context.py\", line 281, in _Popen\n    return Popen(process_obj)\n", "  File \"/usr/local/lib/python3.10/multiprocessing/popen_fork.py\", line 19, in __init__\n    self._launch(process_obj)\n", "  File \"/usr/local/lib/python3.10/multiprocessing/popen_fork.py\", line 71, in _launch\n    code = process_obj._bootstrap(parent_sentinel=child_r)\n", "  File \"/usr/local/lib/python3.10/multiprocessing/process.py\", line 314, in _bootstrap\n    self.run()\n", "  File \"/usr/local/lib/python3.10/site-packages/newrelic/api/background_task.py\", line 117, in wrapper\n    return wrapped(*args, **kwargs)\n", "  File \"/usr/local/lib/python3.10/site-packages/mage_ai/orchestration/queue/process_queue.py\", line 315, in run\n    start_session_and_run(args[1], *args[2], **args[3])\n", "  File \"/usr/local/lib/python3.10/site-packages/mage_ai/orchestration/db/process.py\", line 15, in start_session_and_run\n    results = target(*args)\n", "  File \"/usr/local/lib/python3.10/site-packages/mage_ai/orchestration/pipeline_scheduler_original.py\", line 1235, in run_block\n    return ExecutorFactory.get_block_executor(\n", "  File \"/usr/local/lib/python3.10/site-packages/mage_ai/data_preparation/executors/block_executor.py\", line 649, in execute\n    self.logger.exception(\n", "  File \"/usr/local/lib/python3.10/site-packages/mage_ai/data_preparation/logging/logger.py\", line 30, in exception\n    self.__send_message('exception', message, **kwargs)\n", "  File \"/usr/local/lib/python3.10/site-packages/mage_ai/data_preparation/logging/logger.py\", line 65, in __send_message\n    data['error_stack'] = traceback.format_stack()\n"], "error_stacktrace": "No module named 'opendatasets'"}
Traceback (most recent call last):
  File "/usr/local/lib/python3.10/site-packages/mage_ai/data_preparation/executors/block_executor.py", line 647, in execute
    result = __execute_with_retry()
  File "/usr/local/lib/python3.10/site-packages/mage_ai/shared/retry.py", line 54, in retry_func
    raise e
  File "/usr/local/lib/python3.10/site-packages/mage_ai/shared/retry.py", line 38, in retry_func
    return func(*args, **kwargs)
  File "/usr/local/lib/python3.10/site-packages/mage_ai/data_preparation/executors/block_executor.py", line 621, in __execute_with_retry
    return self._execute(
  File "/usr/local/lib/python3.10/site-packages/mage_ai/data_preparation/executors/block_executor.py", line 1154, in _execute
    result = self.block.execute_sync(
  File "/usr/local/lib/python3.10/site-packages/mage_ai/data_preparation/models/block/__init__.py", line 1691, in execute_sync
    return __execute()
  File "/usr/local/lib/python3.10/site-packages/mage_ai/data_preparation/models/block/__init__.py", line 1668, in __execute
    raise err
  File "/usr/local/lib/python3.10/site-packages/mage_ai/data_preparation/models/block/__init__.py", line 1570, in __execute
    output = self.execute_block(
  File "/usr/local/lib/python3.10/site-packages/mage_ai/data_preparation/models/block/__init__.py", line 1910, in execute_block
    outputs = self._execute_block(
  File "/usr/local/lib/python3.10/site-packages/mage_ai/data_preparation/models/block/__init__.py", line 2041, in _execute_block
    exec(self.content, results)
  File "<string>", line 5, in <module>
ModuleNotFoundError: No module named 'opendatasets'
